I'm sorry, but an uncaught exception occurred.

While running game code:
  File "game/script.rpy", line 945, in script
    if good_condition == 1:
  File "game/script.rpy", line 945, in <module>
    if good_condition == 1:
NameError: name 'good_condition' is not defined

-- Full Traceback ------------------------------------------------------------

Full traceback:
  File "game/script.rpy", line 945, in script
    if good_condition == 1:
  File "D:\Visual novel\renpy\ast.py", line 2133, in execute
    if renpy.python.py_eval(condition):
  File "D:\Visual novel\renpy\python.py", line 1153, in py_eval
    return py_eval_bytecode(code, globals, locals)
  File "D:\Visual novel\renpy\python.py", line 1146, in py_eval_bytecode
    return eval(bytecode, globals, locals)
  File "game/script.rpy", line 945, in <module>
    if good_condition == 1:
NameError: name 'good_condition' is not defined

Windows-10-10.0.22621 AMD64
Ren'Py 8.1.3.23091805
{b}{color=#000000}Замерзающие надежды{/color}{b} 0.1
Mon Dec 25 18:32:15 2023
